2024-10-28 15:38:17,053 - ERROR - Traceback (most recent call last):
2024-10-28 15:38:17,055 - ERROR - File "c:\Users\uiv55706\OneDrive - Vitesco Technologies\DEV\UnitIDsearch\UnitIDsearch.py", line 465, in <module>
2024-10-28 15:38:17,055 - ERROR - background_image = background_image.resize((1720, 820), Image.ANTIALIAS)  # Resize image to fit the window
2024-10-28 15:38:17,056 - ERROR - ^
2024-10-28 15:38:17,056 - ERROR - ^
2024-10-28 15:38:17,056 - ERROR - ^
2024-10-28 15:38:17,056 - ERROR - ^
2024-10-28 15:38:17,057 - ERROR - ^
2024-10-28 15:38:17,057 - ERROR - ^
2024-10-28 15:38:17,057 - ERROR - ^
2024-10-28 15:38:17,057 - ERROR - ^
2024-10-28 15:38:17,059 - ERROR - ^
2024-10-28 15:38:17,059 - ERROR - ^
2024-10-28 15:38:17,059 - ERROR - ^
2024-10-28 15:38:17,059 - ERROR - ^
2024-10-28 15:38:17,060 - ERROR - ^
2024-10-28 15:38:17,060 - ERROR - ^
2024-10-28 15:38:17,060 - ERROR - ^
2024-10-28 15:38:17,060 - ERROR - AttributeError
2024-10-28 15:38:17,061 - ERROR - :
2024-10-28 15:38:17,061 - ERROR - module 'PIL.Image' has no attribute 'ANTIALIAS'
2024-10-28 15:38:54,804 - ERROR - Traceback (most recent call last):
2024-10-28 15:38:54,804 - ERROR - File "c:\Users\uiv55706\OneDrive - Vitesco Technologies\DEV\UnitIDsearch\UnitIDsearch.py", line 466, in <module>
2024-10-28 15:38:54,804 - ERROR - background_photo = ImageTk.PhotoImage(background_image)
2024-10-28 15:38:54,804 - ERROR - ^
2024-10-28 15:38:54,804 - ERROR - ^
2024-10-28 15:38:54,804 - ERROR - ^
2024-10-28 15:38:54,804 - ERROR - ^
2024-10-28 15:38:54,804 - ERROR - ^
2024-10-28 15:38:54,804 - ERROR - ^
2024-10-28 15:38:54,804 - ERROR - ^
2024-10-28 15:38:54,804 - ERROR - ^
2024-10-28 15:38:54,804 - ERROR - ^
2024-10-28 15:38:54,804 - ERROR - ^
2024-10-28 15:38:54,804 - ERROR - ^
2024-10-28 15:38:54,804 - ERROR - ^
2024-10-28 15:38:54,804 - ERROR - ^
2024-10-28 15:38:54,804 - ERROR - ^
2024-10-28 15:38:54,804 - ERROR - ^
2024-10-28 15:38:54,804 - ERROR - ^
2024-10-28 15:38:54,804 - ERROR - ^
2024-10-28 15:38:54,804 - ERROR - ^
2024-10-28 15:38:54,804 - ERROR - ^
2024-10-28 15:38:54,804 - ERROR - ^
2024-10-28 15:38:54,804 - ERROR - ^
2024-10-28 15:38:54,804 - ERROR - ^
2024-10-28 15:38:54,804 - ERROR - ^
2024-10-28 15:38:54,810 - ERROR - ^
2024-10-28 15:38:54,810 - ERROR - ^
2024-10-28 15:38:54,810 - ERROR - ^
2024-10-28 15:38:54,810 - ERROR - ^
2024-10-28 15:38:54,810 - ERROR - ^
2024-10-28 15:38:54,810 - ERROR - ^
2024-10-28 15:38:54,810 - ERROR - ^
2024-10-28 15:38:54,810 - ERROR - ^
2024-10-28 15:38:54,810 - ERROR - ^
2024-10-28 15:38:54,812 - ERROR - ^
2024-10-28 15:38:54,812 - ERROR - ^
2024-10-28 15:38:54,812 - ERROR - ^
2024-10-28 15:38:54,812 - ERROR - ^
2024-10-28 15:38:54,812 - ERROR - File "c:\Users\uiv55706\AppData\Local\Programs\Python\Python312\Lib\site-packages\PIL\ImageTk.py", line 128, in __init__
2024-10-28 15:38:54,834 - ERROR - self.__photo = tkinter.PhotoImage(**kw)
2024-10-28 15:38:54,834 - ERROR - ^
2024-10-28 15:38:54,835 - ERROR - ^
2024-10-28 15:38:54,835 - ERROR - ^
2024-10-28 15:38:54,835 - ERROR - ^
2024-10-28 15:38:54,836 - ERROR - ^
2024-10-28 15:38:54,836 - ERROR - ^
2024-10-28 15:38:54,836 - ERROR - ^
2024-10-28 15:38:54,837 - ERROR - ^
2024-10-28 15:38:54,837 - ERROR - ^
2024-10-28 15:38:54,837 - ERROR - ^
2024-10-28 15:38:54,837 - ERROR - ^
2024-10-28 15:38:54,837 - ERROR - ^
2024-10-28 15:38:54,838 - ERROR - ^
2024-10-28 15:38:54,838 - ERROR - ^
2024-10-28 15:38:54,838 - ERROR - ^
2024-10-28 15:38:54,838 - ERROR - ^
2024-10-28 15:38:54,838 - ERROR - ^
2024-10-28 15:38:54,838 - ERROR - ^
2024-10-28 15:38:54,839 - ERROR - ^
2024-10-28 15:38:54,839 - ERROR - ^
2024-10-28 15:38:54,839 - ERROR - ^
2024-10-28 15:38:54,839 - ERROR - ^
2024-10-28 15:38:54,840 - ERROR - ^
2024-10-28 15:38:54,840 - ERROR - ^
2024-10-28 15:38:54,840 - ERROR - File "c:\Users\uiv55706\AppData\Local\Programs\Python\Python312\Lib\tkinter\__init__.py", line 4162, in __init__
2024-10-28 15:38:54,884 - ERROR - Image.__init__(self, 'photo', name, cnf, master, **kw)
2024-10-28 15:38:54,885 - ERROR - File "c:\Users\uiv55706\AppData\Local\Programs\Python\Python312\Lib\tkinter\__init__.py", line 4099, in __init__
2024-10-28 15:38:54,886 - ERROR - master = _get_default_root('create image')
2024-10-28 15:38:54,887 - ERROR - ^
2024-10-28 15:38:54,887 - ERROR - ^
2024-10-28 15:38:54,887 - ERROR - ^
2024-10-28 15:38:54,887 - ERROR - ^
2024-10-28 15:38:54,887 - ERROR - ^
2024-10-28 15:38:54,887 - ERROR - ^
2024-10-28 15:38:54,888 - ERROR - ^
2024-10-28 15:38:54,888 - ERROR - ^
2024-10-28 15:38:54,888 - ERROR - ^
2024-10-28 15:38:54,888 - ERROR - ^
2024-10-28 15:38:54,888 - ERROR - ^
2024-10-28 15:38:54,888 - ERROR - ^
2024-10-28 15:38:54,890 - ERROR - ^
2024-10-28 15:38:54,890 - ERROR - ^
2024-10-28 15:38:54,890 - ERROR - ^
2024-10-28 15:38:54,890 - ERROR - ^
2024-10-28 15:38:54,890 - ERROR - ^
2024-10-28 15:38:54,890 - ERROR - ^
2024-10-28 15:38:54,891 - ERROR - ^
2024-10-28 15:38:54,891 - ERROR - ^
2024-10-28 15:38:54,891 - ERROR - ^
2024-10-28 15:38:54,891 - ERROR - ^
2024-10-28 15:38:54,891 - ERROR - ^
2024-10-28 15:38:54,892 - ERROR - ^
2024-10-28 15:38:54,892 - ERROR - ^
2024-10-28 15:38:54,892 - ERROR - ^
2024-10-28 15:38:54,892 - ERROR - ^
2024-10-28 15:38:54,893 - ERROR - ^
2024-10-28 15:38:54,893 - ERROR - ^
2024-10-28 15:38:54,894 - ERROR - ^
2024-10-28 15:38:54,894 - ERROR - ^
2024-10-28 15:38:54,894 - ERROR - ^
2024-10-28 15:38:54,894 - ERROR - ^
2024-10-28 15:38:54,894 - ERROR - File "c:\Users\uiv55706\AppData\Local\Programs\Python\Python312\Lib\tkinter\__init__.py", line 323, in _get_default_root
2024-10-28 15:38:54,895 - ERROR - raise RuntimeError(f"Too early to {what}: no default root window")
2024-10-28 15:38:54,895 - ERROR - RuntimeError
2024-10-28 15:38:54,895 - ERROR - :
2024-10-28 15:38:54,895 - ERROR - Too early to create image: no default root window
2025-04-11 09:34:42,493 - INFO - Processing drive: Test SCR_local_P70 at path: C:\Users\uiv55706\OneDrive - Vitesco Technologies\MES\MES_Clients\1.2.2. SCR_VA\Rework
2025-04-11 09:34:42,527 - INFO - Calling process_file_uids with file path: C:\Users\uiv55706\OneDrive - Vitesco Technologies\MES\MES_Clients\1.2.2. SCR_VA\Rework\GHP_2.25.4.9_P70SCR\Logs\tracer.txt
2025-04-11 09:34:42,528 - INFO - Processing file path in process_file_uids: C:\Users\uiv55706\OneDrive - Vitesco Technologies\MES\MES_Clients\1.2.2. SCR_VA\Rework\GHP_2.25.4.9_P70SCR\Logs\tracer.txt
2025-04-11 09:34:42,529 - INFO - Extracted station name in process_file_uids:
